File: data/input/MnO2_Unmilled_Air_25to1100øC_1.XRDML
<?xml version="1.0" encoding="UTF-8"?>
<xrdMeasurements xmlns="http://www.xrdml.com/XRDMeasurement/1.5" xmlns:xsi="http://www.w3.org/2001/XMLSchema-instance" xsi:schemaLocation="http://www.xrdml.com/XRDMeasurement/1.5 http://www.xrdml.com/XRDMeasurement/1.5/XRDMeasurement.xsd" status="Completed">
	<comment>
		<entry>Configuration=HTK 1200N "Ramp", Owner=User-1, Creation date=8/23/2013 9:15:11 AM</entry>
		<entry>Goniometer=Theta/Theta; Minimum step size 2Theta:0.0001; Minimum step size Omega:0.0001</entry>
		<entry>Sample stage=AP HTK-1200N oven with z-axis; Minimum step size Z:0.001</entry>
		<entry>Diffractometer system=EMPYREAN</entry>
		<entry>Measurement program=C:\PANalytical\Data Collector\Programs\Leah Bellcase\REU\Single scan HTK1200.xrdmp, Identifier={110638C9-263E-4C8D-8D94-CB0D50489C22}</entry>
		<entry>Batch program=C:\PANalytical\Data Collector\Programs\Leah Bellcase\REU\Non-ambient Program.xrdmp, Identifier={9A751AF7-7BF6-49D9-BB64-9CD4C1671986}</entry>
		<entry></entry>
	</comment>
	<xrdMeasurement sampleMode="Reflection" measurementType="Scan" status="Completed">
		<usedWavelength intended="K-Alpha 1">
			<kAlpha1 unit="Angstrom">1.540598</kAlpha1>
			<kAlpha2 unit="Angstrom">1.544426</kAlpha2>
			<kBeta unit="Angstrom">1.392250</kBeta>
			<ratioKAlpha2KAlpha1>0.500000</ratioKAlpha2KAlpha1>
		</usedWavelength>
		<incidentBeamPath>
			<radius unit="mm">240.000</radius>
			<xRayTube>
				<tension unit="kV">45</tension>
				<current unit="mA">40</current>
				<anodeMaterial>Cu</anodeMaterial>
			</xRayTube>
			<divergenceSlit xsi:type="fixedDivergenceSlitType">
				<angle unit="deg">0.250</angle>
			</divergenceSlit>
		</incidentBeamPath>
		<diffractedBeamPath>
			<radius unit="mm">240.000</radius>
			<receivingSlit>
				<height unit="mm">0.100</height>
			</receivingSlit>
		</diffractedBeamPath>
		<scan appendNumber="0" scanAxis="Gonio" mode="Continuous" status="Completed">
			<header>
				<startTimeStamp>2022-01-10T10:32:09--05:00</startTimeStamp>
				<author>
					<name>NCSU-XRD</name>
				</author>
				<source>
					<applicationSoftware version="4.7.0">HighScore Plus</applicationSoftware>
				</source>
			</header>
			<dataPoints>
				<positions axis="2Theta" unit="deg">
					<startPosition>10.007</startPosition>
					<endPosition>79.986</endPosition>
				</positions>
				<commonCountingTime unit="seconds">1.020</commonCountingTime>
				<intensities unit="counts">54 52 48 63 55 56 39 45 54 50 48 44 53 44 42 54 46 50 44 56 55 60 58 40 50 49 46 58 61 52 54 59 66 59 57 62 60 48 50 45 40 46 49 47 44 50 53 50 55 52 55 54 43 46 49 45 45 46 47 54 49 48 53 51 43 38 48 58 60 54 58 48 54 46 49 49 47 56 61 56 52 42 48 46 48 50 45 51 49 55 38 44 52 42 47 38 38 57 46 64 64 70 50 50 53 45 51 49 48 47 49 49 54 39 40 49 54 52 40 40 47 50 53 52 54 56 49 50 58 61 53 51 49 49 55 49 46 56 51 47 53 46 51 61 55 56 48 37 42 44 52 56 52 57 54 50 55 51 47 51 46 43 54 54 44 45 48 53 44 50 53 61 60 57 51 39 51 39 36 44 40 49 53 62 71 53 49 45 44 59 67 35 41 44 49 49 44 53 51 37 45 48 46 42 54 44 54 57 61 52 56 41 32 51 61 55 48 39 43 33 56 50 37 48 62 48 47 50 44 43 41 44 51 51 43 45 51 46 44 45 41 49 52 47 50 58 50 46 48 49 54 57 52 44 44 49 45 43 47 49 50 44 46 55 56 48 45 50 45 49 46 43 47 64 55 54 42 46 48 40 40 48 52 43 44 46 53 52 57 53 49 51 40 47 44 40 48 59 44 48 37 36 43 45 40 44 48 41 44 48 44 33 40 40 53 59 39 39 45 45 56 44 47 42 40 45 39 36 39 53 49 41 48 49 54 50 43 45 50 45 37 45 45 42 40 44 45 38 38 42 41 47 46 41 43 40 41 44 37 31 40 45 41 37 42 46 42 48 49 43 51 41 38 39 48 49 57 56 41 36 36 44 48 47 42 30 38 45 52 48 41 28 45 40 39 46 50 52 47 33 38 55 56 47 43 33 34 27 32 39 32 49 54 41 36 39 33 38 38 31 38 41 46 54 46 38 38 43 42 50 41 40 47 38 42 41 39 47 50 45 39 38 37 43 46 41 37 42 41 36 36 38 40 35 38 41 36 38 42 47 47 44 43 44 37 36 38 44 45 45 47 33 36 37 39 48 51 41 42 42 39 37 38 38 44 43 35 33 50 33 33 38 49 40 44 30 41 32 36 33 46 44 48 51 41 51 48 40 43 41 54 47 31 32 39 50 43 28 39 45 33 42 44 45 47 46 44 41 46 46 40 34 34 38 43 44 42 38 42 39 33 33 35 32 35 35 35 33 41 43 40 44 45 42 48 50 41 38 44 43 36 34 31 39 43 38 37 33 32 36 43 45 39 36 33 38 36 40 40 42 43 40 41 47 33 39 38 33 39 37 41 29 32 33 29 36 45 39 32 39 43 29 36 32 34 30 32 29 36 28 42 32 39 36 34 27 31 36 36 37 36 32 37 39 41 42 36 29 28 30 37 29 28 31 34 36 35 38 49 49 39 37 38 33 32 36 38 41 39 32 32 32 32 27 29 30 24 31 41 40 33 32 33 38 39 34 28 34 34 36 39 40 33 38 46 41 33 36 38 40 37 37 41 38 34 28 33 28 35 34 32 28 33 44 37 36 40 33 32 36 37 37 43 42 38 40 34 38 37 33 34 43 30 27 40 36 39 45 33 33 36 42 36 36 31 32 29 29 29 27 41 38 34 32 31 30 34 38 34 32 46 40 37 35 39 39 30 27 32 35 27 28 32 33 39 34 29 27 31 36 40 39 28 31 31 34 42 44 34 32 36 32 38 32 30 38 45 43 32 38 41 40 33 39 42 34 36 33 29 29 39 40 28 34 33 38 42 32 37 42 27 32 20 34 30 46 36 36 33 37 32 40 48 31 33 29 26 22 26 30 39 51 38 31 31 41 40 31 28 34 34 34 42 41 38 35 35 41 32 30 34 35 32 31 35 35 36 32 33 31 33 34 34 30 24 30 29 27 26 26 32 35 38 33 31 36 42 44 37 37 36 26 30 41 35 30 37 30 32 34 35 29 22 24 35 38 38 26 31 29 30 24 28 41 34 23 25 36 35 39 37 32 28 22 31 42 35 42 19 40 29 33 38 23 25 29 24 32 32 28 36 35 29 31 38 35 29 33 38 40 26 27 30 33 34 39 36 35 30 29 25 31 36 33 30 26 27 30 33 32 28 33 35 35 35 36 28 27 36 39 38 35 34 30 31 32 32 37 32 37 37 25 30 32 31 29 32 38 33 33 34 36 23 25 30 23 29 31 45 31 25 33 30 34 27 29 30 35 39 26 34 35 26 40 35 25 25 26 39 31 33 43 37 30 33 34 34 27 36 35 29 34 33 32 39 28 29 36 31 40 36 41 44 39 33 36 37 27 29 30 29 31 33 31 30 30 31 35 33 37 36 33 36 36 38 40 35 33 39 40 36 30 24 26 29 34 35 32 28 29 35 34 32 34 42 42 38 38 30 28 34 31 25 27 26 27 34 36 36 33 40 35 34 38 36 33 30 32 32 34 30 33 43 39 33 23 31 29 36 37 38 26 29 42 46 36 27 20 30 27 29 32 33 30 33 27 32 19 39 41 29 24 24 29 31 32 29 34 27 30 28 29 30 37 32 31 33 37 35 29 29 26 29 31 31 35 33 28 23 28 33 27 32 36 31 37 39 31 24 32 37 34 31 27 28 33 30 25 33 34 25 34 41 38 39 37 29 31 36 33 31 27 40 31 37 33 36 33 31 30 30 23 36 28 28 23 38 36 37 22 23 34 30 37 35 27 27 34 28 35 23 24 47 34 29 40 33 34 32 25 31 38 30 30 27 27 41 34 34 30 27 29 33 30 30 29 31 29 37 40 36 35 37 32 32 33 34 32 26 35 38 29 29 31 36 37 39 38 29 26 30 33 25 24 29 26 30 24 28 29 31 35 28 29 30 36 33 31 35 33 31 30 35 31 35 26 29 26 37 32 24 36 26 29 37 39 42 30 32 39 35 29 34 44 30 34 26 31 33 35 31 27 36 35 44 34 35 33 34 45 42 42 37 23 30 34 31 27 25 33 30 32 28 34 38 38 31 30 34 32 34 29 29 31 34 33 30 36 38 33 29 27 28 30 27 24 29 30 31 25 23 28 31 33 26 25 28 35 38 35 28 31 38 34 27 33 41 42 35 34 30 27 34 35 36 30 34 27 25 31 42 36 27 32 34 30 39 29 27 28 38 32 34 30 38 34 30 39 43 42 44 49 42 44 30 44 41 54 66 67 67 66 98 108 121 140 159 217 293 345 420 453 403 316 260 250 250 228 191 151 104 66 63 67 54 51 51 45 45 41 34 38 35 29 31 32 32 32 31 35 32 30 34 32 39 43 33 30 30 34 36 29 33 35 34 35 23 31 29 32 32 30 30 33 27 24 32 34 33 45 37 27 33 26 33 37 29 33 24 35 32 23 30 34 41 29 25 39 30 25 40 34 22 25 21 24 26 27 28 25 31 36 30 27 31 31 28 31 32 28 28 23 25 33 30 26 28 31 33 29 25 26 31 31 30 29 30 35 35 32 32 28 27 31 31 35 31 27 34 34 30 27 23 32 35 29 30 33 33 28 29 38 32 24 28 27 36 29 27 27 31 25 23 28 26 30 29 33 32 26 28 35 38 29 30 25 26 32 26 33 28 38 23 19 32 38 32 40 30 25 27 21 30 22 41 29 23 28 32 35 24 38 29 28 29 32 28 36 30 29 31 27 30 29 23 32 36 33 37 36 35 28 25 33 35 30 26 32 35 33 31 26 28 35 36 35 31 33 31 23 29 30 26 23 24 36 41 37 29 30 29 28 28 27 30 30 24 20 23 30 32 31 28 29 35 33 29 30 42 26 25 27 31 19 32 37 37 32 25 24 22 35 30 32 33 30 31 27 31 28 22 25 26 35 26 29 22 24 22 38 27 22 20 22 28 27 31 35 28 19 31 30 29 28 27 28 24 22 27 28 31 34 33 32 28 24 23 26 26 23 23 24 30 29 26 32 34 28 26 28 28 27 28 26 29 34 27 25 30 33 29 32 28 20 26 30 33 35 33 42 34 32 25 22 29 23 27 28 28 37 34 29 16 23 41 21 25 26 23 29 30 25 26 28 29 27 31 30 31 22 30 35 28 31 32 36 40 37 40 25 28 36 33 34 32 36 35 32 26 28 28 29 28 23 29 28 22 32 24 22 19 27 31 28 27 29 30 34 34 28 29 35 28 24 26 23 27 29 32 32 27 32 31 23 27 29 32 26 19 20 24 33 31 30 30 25 30 26 26 24 27 35 21 26 28 33 28 32 28 27 30 23 25 31 35 32 27 30 27 34 31 28 29 37 29 34 14 30 23 37 27 37 20 17 23 30 22 21 38 31 28 25 30 39 26 25 34 22 24 28 26 27 37 35 33 29 24 20 22 22 23 27 21 26 26 29 32 31 30 32 26 21 22 23 23 19 21 30 33 27 25 30 27 22 23 27 29 33 33 33 28 20 22 21 27 28 24 25 24 24 32 26 25 29 32 25 32 27 20 27 24 25 22 19 20 24 25 22 32 31 30 31 28 30 23 20 29 31 26 21 21 30 25 37 34 25 24 21 23 26 32 25 32 31 41 33 23 20 25 23 22 31 28 27 25 23 25 32 32 27 27 29 32 29 32 30 20 20 19 28 28 24 28 29 23 23 33 37 29 24 31 32 29 28 27 32 36 38 32 24 31 33 27 27 29 28 24 18 29 29 28 35 35 37 34 28 32 40 33 43 48 59 37 54 54 80 92 87 93 93 105 86 51 55 69 69 70 55 54 47 47 36 30 36 30 25 39 27 29 28 23 31 28 26 30 20 36 30 22 20 20 23 24 31 30 23 24 26 31 34 29 29 24 22 23 28 27 27 24 28 30 27 25 21 18 24 28 25 30 34 28 28 32 32 28 26 26 31 34 26 27 30 24 19 25 41 42 31 22 27 26 27 22 24 33 28 28 28 30 28 26 28 31 33 27 29 33 29 29 22 27 29 30 20 22 23 18 26 36 30 27 36 25 24 22 22 26 29 25 27 17 29 25 25 26 19 27 32 23 25 28 22 21 24 29 24 26 27 28 27 23 26 29 29 25 24 28 29 22 25 26 25 25 27 31 31 24 19 20 29 29 21 24 28 26 25 27 27 28 25 23 28 27 23 25 27 27 23 20 25 35 23 25 25 21 26 25 26 24 26 27 37 27 20 29 31 14 18 25 24 25 28 27 21 25 22 26 20 38 28 20 25 25 32 24 22 34 30 34 33 30 29 24 33 27 19 24 27 35 27 27 27 24 31 36 32 26 28 33 29 38 29 23 23 29 29 23 25 28 26 27 28 32 26 25 27 24 22 24 26 24 28 30 25 26 32 33 27 29 30 35 37 29 33 34 46 50 46 46 50 49 47 42 48 30 31 40 33 36 28 38 38 28 31 25 31 30 28 25 27 23 30 31 31 21 19 29 33 18 21 21 29 25 28 31 29 32 32 26 32 18 25 25 22 29 29 28 23 20 22 29 28 28 27 24 26 29 33 30 29 28 26 27 34 29 28 26 22 26 23 26 32 29 27 22 20 24 25 23 26 33 32 27 25 22 28 25 20 25 23 29 34 23 22 23 26 26 20 18 17 26 25 24 29 32 30 28 28 33 29 29 23 17 27 23 27 25 27 34 25 22 24 27 30 17 26 23 20 30 37 32 32 41 35 24 35 54 46 56 42 40 33 35 41 39 41 38 26 31 36 29 36 32 27 24 25 18 26 27 22 24 31 29 23 24 20 22 26 25 24 27 25 31 28 22 22 26 28 22 23 26 24 30 29 22 21 19 26 30 28 29 29 29 36 32 27 27 20 27 28 20 22 22 28 24 18 23 20 26 20 25 22 22 31 29 32 25 20 30 36 32 30 31 25 16 31 25 27 20 26 21 23 33 24 25 20 25 28 20 24 28 24 24 17 26 20 27 31 24 26 26 32 21 23 27 25 24 25 26 20 21 24 18 18 23 27 33 29 31 29 28 32 28 30 24 21 21 26 23 17 18 23 27 27 26 21 22 26 26 22 24 28 27 27 21 21 29 27 26 22 23 30 22 27 26 23 25 27 24 20 24 20 23 27 32 28 18 21 30 27 21 28 24 26 29 25 21 22 26 29 34 33 23 19 17 29 24 27 29 20 25 21 19 23 29 28 27 26 20 26 25 22 24 30 30 22 26 24 28 24 28 24 22 30 27 20 24 21 17 19 25 27 24 21 24 31 25 22 27 26 26 28 28 28 31 33 33 31 29 29 36 39 39 37 32 31 29 43 41 35 31 35 41 37 32 29 23 24 32 23 26 24 24 19 25 23 19 25 25 26 28 23 21 26 27 29 27 28 25 25 29 33 21 38 28 23 26 27 35 26 23 23 24 32 28 26 23 28 23 24 29 23 22 24 23 33 27 27 19 21 35 31 22 21 26 24 22 27 32 33 22 18 18 20 27 30 27 27 27 30 25 23 25 23 23 22 20 20 22 26 32 34 23 23 26 16 19 30 25 20 20 25 27 26 27 28 29 20 26 25 24 27 29 20 25 26 27 21 38 22 21 36 20 20 25 22 29 27 22 22 23 30 23 32 29 24 18 23 28 25 19 21 32 27 22 28 31 26 21 19 19 28 24 21 25 26 27 27 23 24 25 23 24 28 21 22 26 22 26 29 22 26 29 31 32 27 20 19 26 22 24 28 29 27 21 20 27 32 28 29 29 25 24 24 30 27 24 23 26 25 30 29 23 25 25 27 24 27 28 25 28 24 27 29 21 21 34 32 32 18 20 27 29 40 26 16 28 14 24 28 23 23 24 24 20 20 24 20 16 27 25 22 23 22 23 30 35 26 34 27 26 25 26 24 31 26 32 23 26 26 35 29 22 24 23 16 20 27 26 26 22 22 25 25 26 25 24 22 23 27 31 34 27 24 23 18 22 21 18 27 32 26 26 25 23 27 27 28 32 24 24 29 24 22 22 21 29 34 31 26 29 27 20 24 21 18 22 30 25 28 28 25 28 22 30 18 25 24 24 23 23 28 18 18 18 28 30 20 30 25 28 16 16 28 25 23 24 32 26 22 22 27 26 25 23 21 25 24 29 22 26 27 26 27 24 26 24 26 26 27 22 26 23 23 32 29 32 32 22 20 20 18 22 23 25 28 28 28 27 26 27 26 31 27 24 30 27 28 32 31 33 26 20 24 23 27 27 27 25 24 23 25 26 22 24 25 27 17 24 27 31 30 30 28 22 25 20 25 22 22 21 30 30 21 23 27 19 14 17 25 25 24 24 28 26 38 35 26 27 24 28 18 24 32 27 26 20 16 22 29 27 27 18 21 24 26 27 19 22 26 28 24 18 19 26 25 21 19 27 28 22 23 22 18 19 19 24 29 28 27 27 27 22 22 27 34 34 25 20 18 19 24 18 23 22 25 25 17 22 27 23 23 21 25 24 25 28 24 31 28 29 25 23 30 22 25 17 23 26 20 19 23 32 25 27 13 19 27 29 30 24 27 19 25 24 28 30 18 25 21 21 24 22 15 19 21 18 23 29 24 16 16 21 31 26 27 29 25 23 18 16 18 27 28 24 23 21 19 26 24 16 16 22 20 20 22 20 26 30 23 18 21 21 21 27 31 31 29 31 24 18 23 27 28 26 20 26 31 26 29 20 19 21 20 29 29 30 21 20 19 23 26 27 18 19 21 20 33 17 16 13 21 29 23 32 24 15 30 33 24 23 23 30 25 30 21 25 10 22 29 28 32 25 28 36 27 24 26 25 32 28 24 19 25 22 21 25 25 22 23 27 24 23 18 20 27 25 27 33 28 18 17 23 25 28 26 19 23 25 21 27 31 26 18 16 23 29 24 23 26 24 28 29 27 24 18 20 20 24 24 19 22 25 23 20 21 31 23 25 23 28 30 31 27 20 35 28 24 22 17 23 33 28 36 18 22 21 26 22 20 20 27 20 29 25 19 25 18 14 20 32 30 20 22 25 24 28 24 22 31 34 31 24 23 21 21 27 28 30 28 31 31 27 30 26 27 31 24 25 32 26 27 42 41 28 25 32 36 36 37 36 38 38 39 41 43 49 64 76 82 85 102 120 111 110 106 92 74 59 59 66 65 69 52 75 81 65 68 62 45 31 36 45 39 31 28 30 29 20 23 20 30 23 27 29 23 22 26 32 33 30 18 36 26 27 25 27 26 21 21 32 24 31 22 23 25 23 27 27 22 19 29 24 23 25 30 21 21 27 24 22 15 18 30 30 32 31 22 17 21 25 30 36 29 20 25 28 24 20 20 21 26 28 23 20 28 33 28 23 16 17 20 23 25 25 23 24 25 24 24 21 26 18 21 22 26 17 24 23 24 26 24 27 32 23 18 18 26 25 22 26 22 31 18 24 21 22 21 19 19 29 29 19 34 25 19 33 25 26 28 28 17 27 32 22 24 24 24 20 19 21 21 23 28 28 25 24 25 29 26 19 20 27 30 29 20 19 23 26 19 20 22 18 19 22 27 26 19 24 30 29 24 26 25 15 16 17 18 23 23 24 30 31 31 32 40 47 41 44 63 66 79 73 59 58 55 42 44 43 34 41 49 54 46 55 44 41 37 30 32 21 34 27 25 29 27 29 33 29 24 26 23 32 31 25 32 28 24 24 25 25 21 29 28 28 24 26 21 21 21 23 17 20 24 16 23 31 26 22 31 31 30 24 29 27 23 19 19 26 27 24 23 24 28 26 24 24 25 26 25 26 24 21 25 27 23 21 22 22 22 23 22 20 18 23 27 27 22 22 27 28 21 20 21 23 22 23 26 32 20 28 23 18 28 33 20 21 23 25 25 33 20 17 22 22 21 28 25 27 24 19 17 20 25 15 26 22 27 18 24 24 23 24 20 21 25 26 23 31 22 17 25 25 21 20 20 16 21 23 23 26 21 21 28 22 23 19 19 26 27 26 27 26 21 22 23 26 19 21 33 32 29 23 21 26 28 28 25 26 25 25 27 27 26 27 26 21 21 22 23 18 20 35 27 24 27 25 28 24 27 29 23 21 17 21 19 23 17 19 16 23 27 25 25 26 23 32 23 18 22 27 24 23 21 22 17 23 14 20 18 30 17 24 14 18 20 24 22 26 21 30 29 27 25 24 19 22 27 27 25 26 25 21 20 22 19 17 18 20 20 20 19 20 23 19 21 29 35 25 18 25 21 17 24 26 19 21 31 24 17 20 22 23 23 22 17 24 26 28 23 24 28 24 21 19 23 21 25 25 24 24 22 25 23 18 22 27 31 26 29 26 15 28 34 28 21 18 26 34 13 17 26 30 17 29 29 22 22 20 17 35 21 23 27 20 19 27 25 23 27 23 23 23 22 22 21 21 25 20 33 25 18 22 27 26 28 27 27 25 26 33 35 26 21 26 27 21 29 30 26 25 26 30 32 31 27 23 26 27 27 26 23 23 19 24 27 17 18 25 26 22 15 22 24 24 24 26 24 21 17 27 26 21 25 31 26 25 24 31 24 33 31 31 27 36 28 15 25 28 35 24 27 23 25 30 25 23 22 17 25 33 27 24 30 22 16 24 26 18 26 20 25 23 21 23 25 22 17 28 27 18 21 21 21 20 25 28 29 27 27 23 22 24 17 21 26 25 25 23 24 25 25 27 28 31 29 25 29 28 22 17 23 25 19 21 21 22 22 25 23 21 22 24 20 20 22 15 19 17 20 25 23 19 25 30 30 29 22 19 18 29 25 16 20 19 20 31 23 32 26 27 15 24 19 17 29 28 21 26 24 24 38 19 21 23 19 19 23 21 22 23 26 25 20 16 15 19 32 24 25 29 26 27 24 22 19 28 25 25 31 29 21 20 22 18 17 25 22 20 19 19 23 26 31 33 32 26 20 25 27 26 26 31 35 26 25 32 27 27 27 35 37 33 33 37 38 30 33 34 26 36 28 42 29 28 30 30 34 36 31 38 31 27 27 29 26 29 26 22 27 22 19 24 27 39 19 30 31 26 22 22 25 28 27 20 23 25 28 16 20 19 27 21 24 23 23 29 22 25 24 21 22 19 17 19 25 28 25 21 22 24 28 21 24 28 26 25 24 24 21 20 27 28 25 29 31 26 25 24 25 29 28 27 26 23 18 18 21 24 25 26 21 18 14 19 18 25 20 17 23 29 24 26 29 31 17 18 20 21 17 25 22 18 25 27 26 27 22 20 26 29 23 20 22 21 26 21 24 18 22 21 25 32 27 24 28 35 30 21 25 16 22 20 18 23 22 20 20 26 20 18 26 22 24 25 23 22 25 24 27 27 27 19 18 23 24 20 21 31 27 20 25 26 25 25 25 21 16 16 18 22 20 19 22 22 25 22 18 21 23 24 19 23 20 15 19 19 25 20 23 24 26 26 18 23 22 28 38 17 16 23 24 23 20 26 24 16 27 19 20 25 19 29 25 21 29 20 28 24 18 18 25 31 25 19 14 13 20 21 22 22 26 29 30 25 18 17 15 23 23 27 33 30 20 21 21 23 25 22 25 27 23 18 21 24 20 22 27 22 21 25 25 23 24 21 20 28 32 25 25 26 21 21 22 21 21 18 20 22 26 29 24 19 22 27 25 25 26 24 27 23 33 24 20 25 31 26 25 27 23 28 26 29 21 19 26 23 27 28 24 20 24 27 21 18 24 26 17 24 19 17 16 31 20 29 33 29 25 24 21 21 25 37 32 32 31 22 18 31 26 19 23 23 23 23 31 36 26 24 20 21 28 21 23 22 24 27 32 30 29 34 36 35 35 39 38 33 34 34 34 37 41 46 49 45 40 45 39 36 45 44 41 46 45 36 36 34 36 45 46 39 35 29 34 36 36 34 34 30 35 28 29 21 29 29 27 28 28 26 28 28 29 26 21 23 31 22 27 17 29 26 24 25 33 28 25 26 27 36 31 24 23 35 32 18 29 28 20 20 27 24 22 20 21 18 24 22 33 41 31 18 19 25 30 30 26 22 26 31 29 31 27 19 15 17 21 23 21 21 25 23 25 22 16 25 24 22 23 19 21 24 23 21 31 31 30 30 31 24 24 25 22 17 17 15 24 31 19 24 16 26 28 18 21 20 20 18 32 25 27 15 14 27 17 22 25 25 21 19 19 20 27 28 27 19 26 24 18 29 22 24 20 28 26 25 25 14 22 30 22 18 23 24 28 30 27 16 18 21 21 23 29 24 19 21 18 19 20 29 29 24 20 20 23 19 20 27 25 21 24 25 21 21 25 20 19 23 22 26 24 24 22 19 20 22 22 21 23 21 30 27 23 32 22 20 23 20 23 17 29 26 27 34 28 23 18 21 23 19 20 20 13 18 26 27 18 16 21 22 16 27 41 23 27 22 15 20 34 23 22 20 17 19 23 31 29 26 23 26 25 19 25 27 22 26 31 25 23 25 22 26 29 24 20 22 20 26 23 20 22 19 20 26 27 27 31 27 22 23 26 28 30 25 21 21 21 22 24 22 23 25 21 17 21 21 24 22 21 23 27 26 23 21 21 25 20 23 16 20 21 20 22 21 21 33 26 25 15 12 16 19 30 32 35 19 22 21 19 31 32 21 14 21 28 28 25 24 17 17 15 16 19 21 18 22 21 24 14 28 30 31 29 22 20 21 22 27 22 17 22 20 19 20 22 28 21 22 25 25 21 19 23 30 32 29 25 19 21 25 29 26 24 28 26 22 16 20 25 29 24 20 29 33 26 21 24 20 21 23 22 19 19 16 24 24 23 25 24 27 24 31 21 19 33 25 22 31 20 25 19 29 18 18 21 24 21 23 25 20 20 21 31 19 27 31 24 25 29 23 21 18 28 30 23 23 25 17 23 21 25 20 22 25 26 22 23 23 17 22 25 22 22 15 18 20 20 22 25 20 20 21 23 23 19 19 22 26 26 29 24 18 22 24 20 17 21 22 23 26 22 20 19 16 16 19 17 18 22 23 17 18 20 25 35 22 22 24 27 20 24 22 24 25 26 22 24 24 19 18 22 26 24 21 24 14 25 19 33 16 26 17 27 32 28 20 18 25 22 18 18 19 15 22 23 20 30 29 28 13 22 23 25 32 32 26 23 26 24 24 27 19 21 17 17 23 20 21 23 24 24 26 26 24 27</intensities>
			</dataPoints>
			<nonAmbientPoints type="Temperature" unit="K">
				<measurementTimes unit="seconds" deltaTime="1">0</measurementTimes>
				<nonAmbientValues>299.565</nonAmbientValues>
			</nonAmbientPoints>
		</scan>
	</xrdMeasurement>
</xrdMeasurements>